Traceback (most recent call last):
  File "/opt/homebrew/anaconda3/lib/python3.8/site-packages/jupyter_cache/executors/utils.py", line 51, in single_nb_execution
    executenb(
  File "/opt/homebrew/anaconda3/lib/python3.8/site-packages/nbclient/client.py", line 1087, in execute
    return NotebookClient(nb=nb, resources=resources, km=km, **kwargs).execute()
  File "/opt/homebrew/anaconda3/lib/python3.8/site-packages/nbclient/util.py", line 74, in wrapped
    return just_run(coro(*args, **kwargs))
  File "/opt/homebrew/anaconda3/lib/python3.8/site-packages/nbclient/util.py", line 53, in just_run
    return loop.run_until_complete(coro)
  File "/opt/homebrew/anaconda3/lib/python3.8/asyncio/base_events.py", line 616, in run_until_complete
    return future.result()
  File "/opt/homebrew/anaconda3/lib/python3.8/site-packages/nbclient/client.py", line 540, in async_execute
    await self.async_execute_cell(
  File "/opt/homebrew/anaconda3/lib/python3.8/site-packages/nbclient/client.py", line 832, in async_execute_cell
    self._check_raise_for_error(cell, exec_reply)
  File "/opt/homebrew/anaconda3/lib/python3.8/site-packages/nbclient/client.py", line 740, in _check_raise_for_error
    raise CellExecutionError.from_cell_and_msg(cell, exec_reply['content'])
nbclient.exceptions.CellExecutionError: An error occurred while executing the following cell:
------------------
with open("datasets/first_names.txt", "r") as f:
    names = f.read().splitlines()

names = sorted(random.sample(names, k=n))
------------------

[0;31m---------------------------------------------------------------------------[0m
[0;31mFileNotFoundError[0m                         Traceback (most recent call last)
[0;32m<ipython-input-3-e61757506c2b>[0m in [0;36m<module>[0;34m[0m
[0;32m----> 1[0;31m [0;32mwith[0m [0mopen[0m[0;34m([0m[0;34m"datasets/first_names.txt"[0m[0;34m,[0m [0;34m"r"[0m[0;34m)[0m [0;32mas[0m [0mf[0m[0;34m:[0m[0;34m[0m[0;34m[0m[0m
[0m[1;32m      2[0m     [0mnames[0m [0;34m=[0m [0mf[0m[0;34m.[0m[0mread[0m[0;34m([0m[0;34m)[0m[0;34m.[0m[0msplitlines[0m[0;34m([0m[0;34m)[0m[0;34m[0m[0;34m[0m[0m
[1;32m      3[0m [0;34m[0m[0m
[1;32m      4[0m [0mnames[0m [0;34m=[0m [0msorted[0m[0;34m([0m[0mrandom[0m[0;34m.[0m[0msample[0m[0;34m([0m[0mnames[0m[0;34m,[0m [0mk[0m[0;34m=[0m[0mn[0m[0;34m)[0m[0;34m)[0m[0;34m[0m[0;34m[0m[0m

[0;31mFileNotFoundError[0m: [Errno 2] No such file or directory: 'datasets/first_names.txt'
FileNotFoundError: [Errno 2] No such file or directory: 'datasets/first_names.txt'

